<?xml version="1.0" ?>
<sdf version="1.6">
  <model name="pcg_door_LHR_from_primitives_no_frame">
    <allow_auto_disable>0</allow_auto_disable>
    <pose frame="">0 0 1 0 -0 0</pose>
    <self_collide>0</self_collide>
    <joint name="hinge" type="revolute">
      <pose frame="">0 0.325 0 0 -0 0</pose>
      <axis>
        <xyz>0 0 1</xyz>
        <limit>
          <upper>0.0</upper>
          <lower>-1.57079632679</lower>
          <effort>-1.0</effort>
          <velocity>-1.0</velocity>
        </limit>
        <dynamics>
          <spring_reference>0.0</spring_reference>
          <spring_stiffness>0.0</spring_stiffness>
          <friction>0.0</friction>
          <damping>0.0</damping>
        </dynamics>
        <use_parent_model_frame>0</use_parent_model_frame>
      </axis>
      <parent>world</parent>
      <child>door</child>
    </joint>
    <static>0</static>
    <link name="door">
      <collision name="collision">
        <geometry>
          <box>
            <size>0.04 0.65 2</size>
          </box>
        </geometry>
        <max_contacts>20</max_contacts>
        <pose frame="">0 0 0 0 -0 0</pose>
      </collision>
      <visual name="visual">
        <geometry>
          <box>
            <size>0.04 0.65 2</size>
          </box>
        </geometry>
        <pose frame="">0 0 0 0 -0 0</pose>
        <cast_shadows>1</cast_shadows>
        <transparency>0.0</transparency>
      </visual>
      <pose frame="">0 0 0 0 -0 0</pose>
      <inertial>
        <pose frame="">0 0 0 0 -0 0</pose>
        <mass>10.0</mass>
        <inertia>
          <ixz>0.0</ixz>
          <ixx>3.68541666667</ixx>
          <ixy>0.0</ixy>
          <izz>0.353416666667</izz>
          <iyy>3.33466666667</iyy>
          <iyz>0.0</iyz>
        </inertia>
      </inertial>
    </link>
  </model>
</sdf>
